Workbook

Sheet COVER PAGE
I1: Project N° | J1: Unit | K1: Document Code | L1: Serial N° | M1: Rev. | N1: Page
I2: 218857C | J2: 00 | K2: PS 1600 | L2: 0001 | M2: A | N2: 1
C4: SOCAR
C5: NEW REFINERY PROJECT
D20: PRICE SCHEDULE for ELECTRICAL WORKS Area Process North
B75: A | E75: 16.02.2026 | F75: FIRST ISSUED
B76: Rev | E76: Date DD/MM/YY | F76: STATUS | H76: WRITTEN BY (name & visa) | K76: CHECKED BY (name & visa) | M76: APPROVED BY (name & visa)
B77: DOCUMENT REVISIONS
B78: Sections changed are identified by a vertical line in the margin
B79: TEN-MBP-Onshore-PS1600-ENG-Rev0
E83: TABLE OF CONTENTS
E87: =E94 -> 1 INTRODUCTION
E89: 2 QUANTITIES AND PRICE SCHEDULES
E94: 1 INTRODUCTION
E97: The purpose of the present document is to set forth the unit price for each Price Item as defined into the Price
E98: Description (PD1600); thereby enabling the calculation of the total direct cost for the Electrical Works to be executed by
E99: SUBCONTRACTOR.

Sheet PS
E1: Project N° | F1: Unit | G1: Document Type - Work Code | H1: Serial N° | I1: Rev. | J1: Page
E2: =+'COVER PAGE'!I2 -> 218857C | F2: =+'COVER PAGE'!J2 -> 00 | G2: =+'COVER PAGE'!K2 -> PS 1600 | H2: =+'COVER PAGE'!L2 -> 0001 | I2: =+'COVER PAGE'!M2 -> A | J2: 2
J4: Bidder to consider Secondary Average Cable length: -secondary cable length for Electrical Tracing System (1650) = 50 lm -secondary cable length for Lighting System (1680) = 50 lm
B9: PRICE SCHEDULE FOR ELECTRICAL WORKS
F10: FCC | G10: ss FCC | H10: Overall QTY | J10: Bidder to Fill Yellow Cells
F11: U58 | G11: SS 00-BA-815 | J11: Productivity | K11: Total Manhours | L11: Direct Unit Price Labour | M11: Direct Unit Price Material | N11: Direct Total Price Material | O11: Direct Total Price Labour | P11: Direct Total Price Material + Labour | V11: 5 | X11: 1
B12: Pay Item | C12: Work description | E12: U.M. | J12: [MHs/u.m] | K12: MHs | L12: [USD/ u.m] | M12: [USD/ u.m] | N12: USD | O12: USD | P12: USD | R12: Unit Material | S12: Total Material | T12: Unit Mh | U12: Total Mh | V12: Unit Lab | W12: Total Lab | X12: Unit Eq | Y12: Total Eq | Z12: Unit Tool | AA12: Total Tool | AB12: Unit Subcon | AC12: Total Subcon | AD12: Total Unit | AE12: Grand Total
B13: SYSTEM 1610 - GROUNDING AND LIGHTNING SYSTEM
B14: 1610.01 | D14: INSTALLATION OF UNDERGROUND GROUNDING CONDUCTOR
B15: 1610.01.01 | D15: Section 25 - 50 mm² | E15: m | F15: 8319 | G15: 313 | H15: =IFERROR(SUM($F15:$G15),"") -> 8632 | J15: 0.2 | K15: =+$H15*J15 -> 1726.4 | L15: 1 | M15: 5 | N15: =+$H15*L15 -> 8632 | O15: =+$H15*M15 -> 43160 | P15: =+SUM(N15:O15) -> 51792 | S15: =+R15*$H15 -> 0 | T15: 0.82 | U15: =+T15*$H15 -> 7078.24 | V15: =+T15*$V$11 -> 4.1 | W15: =+V15*$H15 -> 35391.2 | X15: 0.15 | Y15: =+X15*$H15 -> 1294.8 | Z15: 0.41 | AA15: =+Z15*$H15 -> 3539.12 | AC15: =+AB15*$H15 -> 0 | AD15: =+R15+V15+X15+Z15+AB15 -> 4.66 | AE15: =+AD15*$H15 -> 40225.12 | AF15: GAS CHEMICAL COMPLEX_CCB - COST
B16: 1610.01.02 | D16: Section 70 - 150 mm² | E16: m | F16: 16923 | G16: 449 | H16: =IFERROR(SUM($F16:$G16),"") -> 17372 | J16: 0.28 | K16: =+$H16*J16 -> 4864.16 | L16: 1.4 | M16: 10.5 | N16: =+$H16*L16 -> 24320.8 | O16: =+$H16*M16 -> 182406 | P16: =+SUM(N16:O16) -> 206726.8 | S16: =+R16*$H16 -> 0 | T16: 0.92 | U16: =+T16*$H16 -> 15982.24 | V16: =+T16*$V$11 -> 4.6 | W16: =+V16*$H16 -> 79911.2 | X16: 0.19 | Y16: =+X16*$H16 -> 3300.68 | Z16: 0.53 | AA16: =+Z16*$H16 -> 9207.16 | AC16: =+AB16*$H16 -> 0 | AD16: =+R16+V16+X16+Z16+AB16 -> 5.32 | AE16: =+AD16*$H16 -> 92419.04
B17: 1610.01.03 | D17: Section 185 - 240 mm² (up to 500 mm2) | E17: m | F17: 0 | G17: 134 | H17: =IFERROR(SUM($F17:$G17),"") -> 134 | J17: 0.36 | K17: =+$H17*J17 -> 48.24 | L17: 1.8 | M17: 19 | N17: =+$H17*L17 -> 241.2 | O17: =+$H17*M17 -> 2546 | P17: =+SUM(N17:O17) -> 2787.2 | S17: =+R17*$H17 -> 0 | U17: =+T17*$H17 -> 0 | V17: =+T17*$V$11 -> 0 | W17: =+V17*$H17 -> 0 | Y17: =+X17*$H17 -> 0 | AA17: =+Z17*$H17 -> 0 | AC17: =+AB17*$H17 -> 0 | AD17: =+R17+V17+X17+Z17+AB17 -> 0 | AE17: =+AD17*$H17 -> 0
B18: 1610.02 | D18: INSTALLATION AND CONNECTION OF ROD WITH INSPECTION PIT | F18: 0 | G18: 0 | H18: =IFERROR(SUM($F18:$G18),"") -> 0
B19: 1610.02.01 | D19: Rod length up to and including 1.5 m | E19: ea | F19: 0 | G19: 0 | H19: =IFERROR(SUM($F19:$G19),"") -> 0
B20: 1610.02.02 | D20: Rod length above 1.5 m, up to and including 3 m | E20: ea | F20: 21 | G20: 21 | H20: =IFERROR(SUM($F20:$G20),"") -> 42 | J20: 3.2 | K20: =+$H20*J20 -> 134.4 | L20: 16 | M20: 75 | N20: =+$H20*L20 -> 672 | O20: =+$H20*M20 -> 3150 | P20: =+SUM(N20:O20) -> 3822 | S20: =+R20*$H20 -> 0 | U20: =+T20*$H20 -> 0 | V20: =+T20*$V$11 -> 0 | W20: =+V20*$H20 -> 0 | Y20: =+X20*$H20 -> 0 | AA20: =+Z20*$H20 -> 0 | AC20: =+AB20*$H20 -> 0 | AD20: =+R20+V20+X20+Z20+AB20 -> 0 | AE20: =+AD20*$H20 -> 0
B21: 1610.02.03 | D21: Rod length above 3 m, up to and including 6.0 m | E21: ea | F21: 0 | G21: 0 | H21: =IFERROR(SUM($F21:$G21),"") -> 0
B22: 1610.03 | D22: INSTALLATION AND CONNECTION OF ROD WITHOUT INSPECTION PIT (DIRECTLY BURIED) | F22: 0 | G22: 0 | H22: =IFERROR(SUM($F22:$G22),"") -> 0
B23: 1610.03.01 | D23: Rod length up to and including 1.5 m | E23: ea | F23: 0 | G23: 0 | H23: =IFERROR(SUM($F23:$G23),"") -> 0
B24: 1610.03.02 | D24: Rod length above 1.5 m, up to and including 3 m | E24: ea | F24: 0 | G24: 0 | H24: =IFERROR(SUM($F24:$G24),"") -> 0
B25: 1610.03.03 | D25: Rod length above 3 m, up to and including 6.0 m | E25: ea | F25: 0 | G25: 0 | H25: =IFERROR(SUM($F25:$G25),"") -> 0
B26: 1610.04 | D26: INSTALLATION OF GROUNDING BAR (DISPATCHER) | F26: 0 | G26: 0 | H26: =IFERROR(SUM($F26:$G26),"") -> 0
B27: 1610.04.01 | D27: Dispatcher on steel/concrete structure direct mounting | E27: ea | F27: 236 | G27: 19 | H27: =IFERROR(SUM($F27:$G27),"") -> 255 | J27: 4 | K27: =+$H27*J27 -> 1020 | L27: 20 | M27: 38 | N27: =+$H27*L27 -> 5100 | O27: =+$H27*M27 -> 9690 | P27: =+SUM(N27:O27) -> 14790 | S27: =+R27*$H27 -> 0 | U27: =+T27*$H27 -> 0 | V27: =+T27*$V$11 -> 0 | W27: =+V27*$H27 -> 0 | Y27: =+X27*$H27 -> 0 | AA27: =+Z27*$H27 -> 0 | AC27: =+AB27*$H27 -> 0 | AD27: =+R27+V27+X27+Z27+AB27 -> 0 | AE27: =+AD27*$H27 -> 0
B28: 1610.04.02 | D28: Dispatcher on independent frame mounting | E28: ea | F28: 0 | G28: 0 | H28: =IFERROR(SUM($F28:$G28),"") -> 0
B29: 1610.04.03 | D29: Substation main grounding bar - tape, aboveground | E29: m | F29: 0 | G29: 77 | H29: =IFERROR(SUM($F29:$G29),"") -> 77 | J29: 1 | K29: =+$H29*J29 -> 77 | L29: 5 | M29: 15 | N29: =+$H29*L29 -> 385 | O29: =+$H29*M29 -> 1155 | P29: =+SUM(N29:O29) -> 1540 | S29: =+R29*$H29 -> 0 | U29: =+T29*$H29 -> 0 | V29: =+T29*$V$11 -> 0 | W29: =+V29*$H29 -> 0 | Y29: =+X29*$H29 -> 0 | AA29: =+Z29*$H29 -> 0 | AC29: =+AB29*$H29 -> 0 | AD29: =+R29+V29+X29+Z29+AB29 -> 0 | AE29: =+AD29*$H29 -> 0
B30: 1610.05 | D30: INSTALLATION OF OVERHEAD CONDUCTOR | F30: 0 | G30: 0 | H30: =IFERROR(SUM($F30:$G30),"") -> 0
B31: 1610.05.01 | D31: Section 25 - 50 mm² | E31: m | F31: 16814 | G31: 163 | H31: =IFERROR(SUM($F31:$G31),"") -> 16977 | J31: 0.25 | K31: =+$H31*J31 -> 4244.25 | L31: 1.25 | M31: 5 | N31: =+$H31*L31 -> 21221.25 | O31: =+$H31*M31 -> 84885 | P31: =+SUM(N31:O31) -> 106106.25 | S31: =+R31*$H31 -> 0 | U31: =+T31*$H31 -> 0 | V31: =+T31*$V$11 -> 0 | W31: =+V31*$H31 -> 0 | Y31: =+X31*$H31 -> 0 | AA31: =+Z31*$H31 -> 0 | AC31: =+AB31*$H31 -> 0 | AD31: =+R31+V31+X31+Z31+AB31 -> 0 | AE31: =+AD31*$H31 -> 0
B32: 1610.05.02 | D32: Section 70 - 150 mm² | E32: m | F32: 11535 | G32: 1182 | H32: =IFERROR(SUM($F32:$G32),"") -> 12717 | J32: 0.32 | K32: =+$H32*J32 -> 4069.44 | L32: 1.6 | M32: 10.5 | N32: =+$H32*L32 -> 20347.2 | O32: =+$H32*M32 -> 133528.5 | P32: =+SUM(N32:O32) -> 153875.7 | S32: =+R32*$H32 -> 0 | U32: =+T32*$H32 -> 0 | V32: =+T32*$V$11 -> 0 | W32: =+V32*$H32 -> 0 | Y32: =+X32*$H32 -> 0 | AA32: =+Z32*$H32 -> 0 | AC32: =+AB32*$H32 -> 0 | AD32: =+R32+V32+X32+Z32+AB32 -> 0 | AE32: =+AD32*$H32 -> 0
B33: 1610.05.03 | D33: Section 185 - 240 mm² (up to 500 mm2) | E33: m | F33: 0 | G33: 190 | H33: =IFERROR(SUM($F33:$G33),"") -> 190 | J33: 0.4 | K33: =+$H33*J33 -> 76 | L33: 2 | M33: 19 | N33: =+$H33*L33 -> 380 | O33: =+$H33*M33 -> 3610 | P33: =+SUM(N33:O33) -> 3990 | S33: =+R33*$H33 -> 0 | U33: =+T33*$H33 -> 0 | V33: =+T33*$V$11 -> 0 | W33: =+V33*$H33 -> 0 | Y33: =+X33*$H33 -> 0 | AA33: =+Z33*$H33 -> 0 | AC33: =+AB33*$H33 -> 0 | AD33: =+R33+V33+X33+Z33+AB33 -> 0 | AE33: =+AD33*$H33 -> 0
B34: 1610.06 | D34: EQUIPMENT/STRUCTURE GROUNDING CONNECTION | F34: 0 | G34: 0 | H34: =IFERROR(SUM($F34:$G34),"") -> 0
B35: 1610.06.01 | D35: Section 25 - 50 mm² | E35: ea | F35: 3677 | G35: 103 | H35: =IFERROR(SUM($F35:$G35),"") -> 3780 | J35: 1.2 | K35: =+$H35*J35 -> 4536 | L35: 6 | M35: 3.5 | N35: =+$H35*L35 -> 22680 | O35: =+$H35*M35 -> 13230 | P35: =+SUM(N35:O35) -> 35910 | S35: =+R35*$H35 -> 0 | U35: =+T35*$H35 -> 0 | V35: =+T35*$V$11 -> 0 | W35: =+V35*$H35 -> 0 | Y35: =+X35*$H35 -> 0 | AA35: =+Z35*$H35 -> 0 | AC35: =+AB35*$H35 -> 0 | AD35: =+R35+V35+X35+Z35+AB35 -> 0 | AE35: =+AD35*$H35 -> 0
B36: 1610.06.02 | D36: Section 70 - 150 mm² | E36: ea | F36: 782 | G36: 383 | H36: =IFERROR(SUM($F36:$G36),"") -> 1165 | J36: 1.6 | K36: =+$H36*J36 -> 1864 | L36: 8 | M36: 6.5 | N36: =+$H36*L36 -> 9320 | O36: =+$H36*M36 -> 7572.5 | P36: =+SUM(N36:O36) -> 16892.5 | S36: =+R36*$H36 -> 0 | U36: =+T36*$H36 -> 0 | V36: =+T36*$V$11 -> 0 | W36: =+V36*$H36 -> 0 | Y36: =+X36*$H36 -> 0 | AA36: =+Z36*$H36 -> 0 | AC36: =+AB36*$H36 -> 0 | AD36: =+R36+V36+X36+Z36+AB36 -> 0 | AE36: =+AD36*$H36 -> 0
B37: 1610.06.03 | D37: Section 185 - 240 mm² (up to 500 mm2) | E37: ea | F37: 0 | G37: 21 | H37: =IFERROR(SUM($F37:$G37),"") -> 21 | J37: 2 | K37: =+$H37*J37 -> 42 | L37: 10 | M37: 11 | N37: =+$H37*L37 -> 210 | O37: =+$H37*M37 -> 231 | P37: =+SUM(N37:O37) -> 441 | S37: =+R37*$H37 -> 0 | U37: =+T37*$H37 -> 0 | V37: =+T37*$V$11 -> 0 | W37: =+V37*$H37 -> 0 | Y37: =+X37*$H37 -> 0 | AA37: =+Z37*$H37 -> 0 | AC37: =+AB37*$H37 -> 0 | AD37: =+R37+V37+X37+Z37+AB37 -> 0 | AE37: =+AD37*$H37 -> 0
B38: 1610.07 | D38: INSTALLATION OF EARTHING LUG | F38: 0 | G38: 0 | H38: =IFERROR(SUM($F38:$G38),"") -> 0
B39: 1610.07.01 | D39: Normal - plate length = 75 mm | E39: ea | F39: 755 | G39: 13 | H39: =IFERROR(SUM($F39:$G39),"") -> 768 | J39: 0.3 | K39: =+$H39*J39 -> 230.4 | L39: 1.5 | M39: 2 | N39: =+$H39*L39 -> 1152 | O39: =+$H39*M39 -> 1536 | P39: =+SUM(N39:O39) -> 2688 | S39: =+R39*$H39 -> 0 | U39: =+T39*$H39 -> 0 | V39: =+T39*$V$11 -> 0 | W39: =+V39*$H39 -> 0 | Y39: =+X39*$H39 -> 0 | AA39: =+Z39*$H39 -> 0 | AC39: =+AB39*$H39 -> 0 | AD39: =+R39+V39+X39+Z39+AB39 -> 0 | AE39: =+AD39*$H39 -> 0
B40: 1610.07.02 | D40: Long - plate length = 150 mm | E40: ea | F40: 0 | G40: 0 | H40: =IFERROR(SUM($F40:$G40),"") -> 0
B41: 1610.08 | D41: INSTALLATION OF LIGHTNING PROTECTION SYSTEM | F41: 0 | G41: 0 | H41: =IFERROR(SUM($F41:$G41),"") -> 0
B42: 1610.08.01 | D42: Lightning conductor - tape, aboveground | E42: m | F42: 756 | G42: 0 | H42: =IFERROR(SUM($F42:$G42),"") -> 756 | J42: 0.28 | K42: =+$H42*J42 -> 211.68 | L42: 1.4 | M42: 8 | N42: =+$H42*L42 -> 1058.4 | O42: =+$H42*M42 -> 6048 | P42: =+SUM(N42:O42) -> 7106.4 | S42: =+R42*$H42 -> 0 | U42: =+T42*$H42 -> 0 | V42: =+T42*$V$11 -> 0 | W42: =+V42*$H42 -> 0 | Y42: =+X42*$H42 -> 0 | AA42: =+Z42*$H42 -> 0 | AC42: =+AB42*$H42 -> 0 | AD42: =+R42+V42+X42+Z42+AB42 -> 0 | AE42: =+AD42*$H42 -> 0
B43: 1610.08.02 | D43: Lightning conductor - wire, aboveground | E43: m | F43: 0 | G43: 0 | H43: =IFERROR(SUM($F43:$G43),"") -> 0
B44: 1610.08.03 | D44: Air terminals | E44: ea | F44: 10 | G44: 0 | H44: =IFERROR(SUM($F44:$G44),"") -> 10 | J44: 1.6 | K44: =+$H44*J44 -> 16 | L44: 8 | M44: 45 | N44: =+$H44*L44 -> 80 | O44: =+$H44*M44 -> 450 | P44: =+SUM(N44:O44) -> 530 | S44: =+R44*$H44 -> 0 | U44: =+T44*$H44 -> 0 | V44: =+T44*$V$11 -> 0 | W44: =+V44*$H44 -> 0 | Y44: =+X44*$H44 -> 0 | AA44: =+Z44*$H44 -> 0 | AC44: =+AB44*$H44 -> 0 | AD44: =+R44+V44+X44+Z44+AB44 -> 0 | AE44: =+AD44*$H44 -> 0
B45: 1610.08.04 | D45: Surge arresters | E45: ea | F45: 0 | G45: 0 | H45: =IFERROR(SUM($F45:$G45),"") -> 0
...
